{"uuid": "0a6d6a20-66c0-4f9a-b21a-01ccf4efa59d", "children": ["902d443e-1146-45fe-a6cb-d3aac006f8d6", "4dca9dfe-4523-488f-bcb5-1cf351667366", "6eac5e37-f28e-4b73-93aa-6ff205e41302"], "befores": [{"name": "init_driver", "status": "passed", "start": 1666254875764, "stop": 1666254878122}], "afters": [{"name": "init_driver::0", "status": "broken", "statusDetails": {"message": "urllib3.exceptions.MaxRetryError: HTTPConnectionPool(host='127.0.0.1', port=50968): Max retries exceeded with url: /session/5efa085db637bc53b075d04e5d18fbfb/cookie/TLTSID (Caused by NewConnectionError('<urllib3.connection.HTTPConnection object at 0x7f8faffaa0d0>: Failed to establish a new connection: [Errno 61] Connection refused'))\n", "trace": "  File \"/Users/atultupe/PycharmProjects/venv/lib/python3.9/site-packages/allure_commons/_allure.py\", line 200, in __call__\n    return self._fixture_function(*args, **kwargs)\n  File \"/Users/atultupe/PycharmProjects/venv/lib/python3.9/site-packages/_pytest/fixtures.py\", line 941, in _teardown_yield_fixture\n    next(it)\n  File \"/Users/atultupe/PycharmProjects/python_pytest/Tests/conftest.py\", line 26, in init_driver\n    SID = driver.get_cookie(\"TLTSID\")\n  File \"/Users/atultupe/PycharmProjects/venv/lib/python3.9/site-packages/selenium/webdriver/remote/webdriver.py\", line 852, in get_cookie\n    return self.execute(Command.GET_COOKIE, {'name': name})['value']\n  File \"/Users/atultupe/PycharmProjects/venv/lib/python3.9/site-packages/selenium/webdriver/remote/webdriver.py\", line 319, in execute\n    response = self.command_executor.execute(driver_command, params)\n  File \"/Users/atultupe/PycharmProjects/venv/lib/python3.9/site-packages/selenium/webdriver/remote/remote_connection.py\", line 374, in execute\n    return self._request(command_info[0], url, body=data)\n  File \"/Users/atultupe/PycharmProjects/venv/lib/python3.9/site-packages/selenium/webdriver/remote/remote_connection.py\", line 397, in _request\n    resp = self._conn.request(method, url, body=body, headers=headers)\n  File \"/Users/atultupe/PycharmProjects/venv/lib/python3.9/site-packages/urllib3/request.py\", line 75, in request\n    return self.request_encode_url(\n  File \"/Users/atultupe/PycharmProjects/venv/lib/python3.9/site-packages/urllib3/request.py\", line 97, in request_encode_url\n    return self.urlopen(method, url, **extra_kw)\n  File \"/Users/atultupe/PycharmProjects/venv/lib/python3.9/site-packages/urllib3/poolmanager.py\", line 336, in urlopen\n    response = conn.urlopen(method, u.request_uri, **kw)\n  File \"/Users/atultupe/PycharmProjects/venv/lib/python3.9/site-packages/urllib3/connectionpool.py\", line 754, in urlopen\n    return self.urlopen(\n  File \"/Users/atultupe/PycharmProjects/venv/lib/python3.9/site-packages/urllib3/connectionpool.py\", line 754, in urlopen\n    return self.urlopen(\n  File \"/Users/atultupe/PycharmProjects/venv/lib/python3.9/site-packages/urllib3/connectionpool.py\", line 754, in urlopen\n    return self.urlopen(\n  File \"/Users/atultupe/PycharmProjects/venv/lib/python3.9/site-packages/urllib3/connectionpool.py\", line 726, in urlopen\n    retries = retries.increment(\n  File \"/Users/atultupe/PycharmProjects/venv/lib/python3.9/site-packages/urllib3/util/retry.py\", line 446, in increment\n    raise MaxRetryError(_pool, url, error or ResponseError(cause))\n"}, "start": 1666254913605, "stop": 1666254913616}], "start": 1666254875764, "stop": 1666254913616}